<robot
  name="abb_irb120_support">
  <link
    name="base_link">
    <inertial>
      <origin
        xyz="-0.042039 8.0132E-05 0.079638"
        rpy="0 0 0" />
      <mass
        value="6.215" />
      <inertia
        ixx="0.024727"
        ixy="-8.0784E-05"
        ixz="0.001309"
        iyy="0.049128"
        iyz="-8.042E-06"
        izz="0.047238" />
    </inertial>
    <visual>
      <origin
        xyz="0 0 0"
        rpy="0 0 0" />
      <geometry>
        <mesh
          filename="package://abb_irb120_support/meshes/base_link.STL" />
      </geometry>
      <material
        name="">
        <color
          rgba="0.75294 0.75294 0.75294 1" />
      </material>
    </visual>
    <collision>
      <origin
        xyz="0 0 0"
        rpy="0 0 0" />
      <geometry>
        <mesh
          filename="package://abb_irb120_support/collision_meshes/base_link_collision.stl" />
      </geometry>
    </collision>
  </link>
  <link
    name="Link1">
    <inertial>
      <origin
        xyz="9.7678E-05 -0.00011928 0.070412"
        rpy="0 0 0" />
      <mass
        value="3.067" />
      <inertia
        ixx="0.014217"
        ixy="-1.2858E-05"
        ixz="-2.3136E-05"
        iyy="0.014404"
        iyz="1.9339E-05"
        izz="0.010453" />
    </inertial>
    <visual>
      <origin
        xyz="0 0 0"
        rpy="0 0 0" />
      <geometry>
        <mesh
          filename="package://abb_irb120_support/meshes/Link1.STL" />
      </geometry>
      <material
        name="">
        <color
          rgba="0.75294 0.75294 0.75294 1" />
      </material>
    </visual>
    <collision>
      <origin
        xyz="0 0 0"
        rpy="0 0 0" />
      <geometry>
        <mesh
          filename="package://abb_irb120_support/collision_meshes/Link1_collision.stl" />
      </geometry>
    </collision>
  </link>
  <joint
    name="Joint1"
    type="revolute">
    <origin
      xyz="0 0 0.168"
      rpy="0 0 0" />
    <parent
      link="base_link" />
    <child
      link="Link1" />
    <axis
      xyz="0 0 1" />
    <limit
      lower="-2.8798"
      upper="2.8798"
      effort="0"
      velocity="4.3633" />
  </joint>
  <link
    name="Link2">
    <inertial>
      <origin
        xyz="0.000778291952838616 -0.00211702803525138 0.101243214883767"
        rpy="0 0 0" />
      <mass
        value="3.90866623830227" />
      <inertia
        ixx="0.0603110976435059"
        ixy="9.83149243751087E-06"
        ixz="5.72406399607017E-05"
        iyy="0.0415689865599529"
        iyz="-0.000504969930501592"
        izz="0.0259548392864131" />
    </inertial>
    <visual>
      <origin
        xyz="0 0 0"
        rpy="0 0 0" />
      <geometry>
        <mesh
          filename="package://abb_irb120_support/meshes/Link2.STL" />
      </geometry>
      <material
        name="">
        <color
          rgba="0.752941176470588 0.752941176470588 0.752941176470588 1" />
      </material>
    </visual>
    <collision>
      <origin
        xyz="0 0 0"
        rpy="0 0 0" />
      <geometry>
        <mesh
          filename="package://abb_irb120_support/collision_meshes/Link2_collision.stl" />
      </geometry>
    </collision>
  </link>
  <joint
    name="Joint2"
    type="revolute">
    <origin
      xyz="0 0 0.122"
      rpy="0 0 0" />
    <parent
      link="Link1" />
    <child
      link="Link2" />
    <axis
      xyz="0 1 0" />
    <limit
      lower="-1.9199"
      upper="1.9199"
      effort="0"
      velocity="1.5708" />
  </joint>
  <link
    name="Link3">
    <inertial>
      <origin
        xyz="0.0228074809994381 0.00120897586284432 0.0579107368179828"
        rpy="0 0 0" />
      <mass
        value="2.9437255083924" />
      <inertia
        ixx="0.00835607306015226"
        ixy="-8.01358877542077E-05"
        ixz="0.00142880988247658"
        iyy="0.0167130296529309"
        iyz="-0.000182237668918122"
        izz="0.0126984927912076" />
    </inertial>
    <visual>
      <origin
        xyz="0 0 0"
        rpy="0 0 0" />
      <geometry>
        <mesh
          filename="package://abb_irb120_support/meshes/Link3.STL" />
      </geometry>
      <material
        name="">
        <color
          rgba="0.752941176470588 0.752941176470588 0.752941176470588 1" />
      </material>
    </visual>
    <collision>
      <origin
        xyz="0 0 0"
        rpy="0 0 0" />
      <geometry>
        <mesh
          filename="package://abb_irb120_support/collision_meshes/Link3_collision.stl" />
      </geometry>
    </collision>
  </link>
  <joint
    name="Joint3"
    type="revolute">
    <origin
      xyz="0 -0.00014469 0.27"
      rpy="0 0 0" />
    <parent
      link="Link2" />
    <child
      link="Link3" />
    <axis
      xyz="0 1 0" />
    <limit
      lower="-1.9199"
      upper="1.2217"
      effort="0"
      velocity="1.5708" />
  </joint>
  <link
    name="Link4">
    <inertial>
      <origin
        xyz="0.0751038433084677 0.000153418182333791 0.000405525366698134"
        rpy="0 0 0" />
      <mass
        value="1.32786423978252" />
      <inertia
        ixx="0.00284661086899562"
        ixy="-2.12765348444726E-05"
        ixz="-1.64352201487469E-05"
        iyy="0.00401345852490699"
        iyz="1.31335897238183E-05"
        izz="0.00525350971191271" />
    </inertial>
    <visual>
      <origin
        xyz="0 0 0"
        rpy="0 0 0" />
      <geometry>
        <mesh
          filename="package://abb_irb120_support/meshes/Link4.STL" />
      </geometry>
      <material
        name="">
        <color
          rgba="0.752941176470588 0.752941176470588 0.752941176470588 1" />
      </material>
    </visual>
    <collision>
      <origin
        xyz="0 0 0"
        rpy="0 0 0" />
      <geometry>
        <mesh
          filename="package://abb_irb120_support/collision_meshes/Link4_collision.stl" />
      </geometry>
    </collision>
  </link>
  <joint
    name="Joint4"
    type="revolute">
    <origin
      xyz="0.1496 0.00014469 0.07"
      rpy="0 0 0" />
    <parent
      link="Link3" />
    <child
      link="Link4" />
    <axis
      xyz="1 0 0" />
    <limit
      lower="-2.7925"
      upper="2.7925"
      effort="0"
      velocity="2.618" />
  </joint>
  <link
    name="Link5">
    <inertial>
      <origin
        xyz="-0.00109483746836125 0.0320368524524147 6.22166698938109E-05"
        rpy="0 0 0" />
      <mass
        value="0.546626845859248" />
      <inertia
        ixx="0.000404891032170954"
        ixy="1.61942918043531E-06"
        ixz="8.46804365684889E-07"
        iyy="0.000892824969239831"
        iyz="-1.51796477263052E-08"
        izz="0.000815468385056356" />
    </inertial>
    <visual>
      <origin
        xyz="0 0 0"
        rpy="0 0 0" />
      <geometry>
        <mesh
          filename="package://abb_irb120_support/meshes/Link5.STL" />
      </geometry>
      <material
        name="">
        <color
          rgba="0.752941176470588 0.752941176470588 0.752941176470588 1" />
      </material>
    </visual>
    <collision>
      <origin
        xyz="0 0 0"
        rpy="0 0 0" />
      <geometry>
        <mesh
          filename="package://abb_irb120_support/collision_meshes/Link5_collision.stl" />
      </geometry>
    </collision>
  </link>
  <joint
    name="Joint5"
    type="revolute">
    <origin
      xyz="0.1524 -0.032 0"
      rpy="0 0 0" />
    <parent
      link="Link4" />
    <child
      link="Link5" />
    <axis
      xyz="0 1 0" />
    <limit
      lower="-2.0944"
      upper="2.0944"
      effort="0"
      velocity="2.0944" />
  </joint>
  <link
    name="Link6">
    <inertial>
      <origin
        xyz="0.0200379127426173 -0.000169581014409805 -1.32366980598597E-06"
        rpy="0 0 0" />
      <mass
        value="0.013678420390067" />
      <inertia
        ixx="2.97681416595681E-06"
        ixy="-7.6625029712154E-09"
        ixz="-8.91499959844029E-11"
        iyy="1.69426726293188E-06"
        iyz="-3.06372609037413E-12"
        izz="1.65769997949113E-06" />
    </inertial>
    <visual>
      <origin
        xyz="0 0 0"
        rpy="0 0 0" />
      <geometry>
        <mesh
          filename="package://abb_irb120_support/meshes/Link6.STL" />
      </geometry>
      <material
        name="">
        <color
          rgba="0.752941176470588 0.752941176470588 0.752941176470588 1" />
      </material>
    </visual>
    <collision>
      <origin
        xyz="0 0 0"
        rpy="0 0 0" />
      <geometry>
        <mesh
          filename="package://abb_irb120_support/collision_meshes/Link6_collision.stl" />
      </geometry>
    </collision>
  </link>
  <joint
    name="Joint6"
    type="revolute">
    <origin
      xyz="0.0449 0.032 0"
      rpy="0 0 0" />
    <parent
      link="Link5" />
    <child
      link="Link6" />
    <axis
      xyz="1 0 0" />
    <limit
      lower="-6.9813"
      upper="6.9813"
      effort="0"
      velocity="3.3161" />
  </joint>
  <link
    name="Link7">
    <inertial>
      <origin
        xyz="0.0601089523443162 0.0175664480188072 -0.00795697526891392"
        rpy="0 0 0" />
      <mass
        value="0.157422249704945" />
      <inertia
        ixx="0.000945041277634227"
        ixy="0.000134505990230202"
        ixz="-3.60207980895639E-05"
        iyy="0.000970220164883578"
        iyz="7.34400740845334E-05"
        izz="0.000575731843595281" />
    </inertial>
    <visual>
      <origin
        xyz="0 0 0"
        rpy="0 0 0" />
      <geometry>
        <mesh
          filename="package://abb_irb120_support/meshes/Link7.STL" />
      </geometry>
      <material
        name="">
        <color
          rgba="0.752941176470588 0.752941176470588 0.752941176470588 1" />
      </material>
    </visual>
    <collision>
      <origin
        xyz="0 0 0"
        rpy="0 0 0" />
      <geometry>
        <mesh
          filename="package://abb_irb120_support/collision_meshes/Link7_collision.stl" />
      </geometry>
    </collision>
  </link>
  <joint
    name="Joint7"
    type="fixed">
    <origin
      xyz="0.0271 -9.6249E-05 0"
      rpy="0 0 0" />
    <parent
      link="Link6" />
    <child
      link="Link7" />
    <axis
      xyz="0 0 0" />
    <limit
      lower="0"
      upper="0"
      effort="0"
      velocity="0" />
  </joint>
</robot>
